<?xml version="1.0" ?>
<robot name="robo_gazebo.urdf" xmlns:xacro="http://ros.org/wiki/xacro">

        
        <material name="black">
        <color rgba="0.0 0.0 0.0 1.0"/>
        </material>
        <material name="blue">
        <color rgba="0.203125 0.23828125 0.28515625 1.0"/>
        </material>
        <material name="green">
        <color rgba="0.0 0.8 0.0 1.0"/>
         </material>
         <material name="grey">
         <color rgba="0.2 0.2 0.2 1.0"/>
         </material>
       <material name="orange">
       <color rgba="1.0 0.423529411765 0.0392156862745 1.0"/>
        </material>
        <material name="brown">
          <color rgba="0.870588235294 0.811764705882 0.764705882353 1.0"/>
       </material>
     <material name="red">
       <color rgba="0.80078125 0.12890625 0.1328125 1.0"/>
      </material>
        <material name="white">
       <color rgba="1.0 1.0 1.0 1.0"/>
       </material> 




<!-- ***************************************************************************************************************************-->
<!-- ***************************************************************************************************************************-->
<!-- ***************************************************************************************************************************-->




      <gazebo reference="base">
      <material>Gazebo/Orange</material>
      </gazebo>
     <gazebo reference="back_left_wheel">
      <material>Gazebo/Blue</material>
      </gazebo>
      <gazebo reference="back_right_wheel">
      <material>Gazebo/Blue</material>
      </gazebo>
      <gazebo reference="front_left_wheel">
      <material>Gazebo/Blue</material>
      </gazebo>
      <gazebo reference="front_right_wheel">
      <material>Gazebo/Blue</material>
      </gazebo>
      <gazebo reference="arm_base">
      <material>Gazebo/Green</material>
      </gazebo>
      <gazebo reference="arm_gun">
      <material>Gazebo/Red</material>
      </gazebo>
 


 <!-- ***************************************************************************************************************************-->
<!-- ***************************************************************************************************************************-->
<!-- ***************************************************************************************************************************-->
     

  <link name = "base">
       <pose>0 0 0.1 0 0 0</pose>
               <inertial>
               <mass value="5"/>
              <origin rpy="0 0 0" xyz="0 0 0.1"/>
              <inertia 
                ixx="0.43333333333" ixy="0" ixz="0" iyy="0.43333333333" iyz="0" izz="0.43333333333"/>
             </inertial>
                 <collision name="base_link">
                <geometry>
                  <box size="1 1 0.2"/>
               </geometry>
             </collision>
  		<visual>
      		<geometry>
        		<box size = '1 1 0.2' />
      		</geometry>
    	</visual>
	</link>

    <link name="camera_link">
    <collision>
      <origin xyz="0 0 0.1" rpy="1.570 0 1.570"/>
      <geometry>
	<box size="0.05 0.05 0.05"/>
      </geometry>
    </collision>

    <visual>
      <origin xyz="0 0 0.1" rpy="1.570 0 1.570"/>
      <geometry>
	<box size="0.05 0.05 0.05"/>
      </geometry>
      <material name="red"/>
    </visual>
    <inertial>
      <mass value="1e-5" />
      <origin xyz="0 0 0.1" rpy="1.570 0 1.570"/>
      <inertia ixx="1e-6" ixy="0" ixz="0" iyy="1e-6" iyz="0" izz="1e-6" />
    </inertial>
  </link>

   <joint name="camera_joint" type="fixed">
    <axis xyz="0 1 0" />
    <origin xyz="0 0.5 0" rpy="0 0 1.570"/>
    <parent link="base"/>
    <child link="camera_link"/>
       </joint>

 <!--  <link name="camera_link_optical">
	</link>-->

	
	<!--<joint name="camera_optical_joint" type="fixed">
         these values have to be these values otherwise the gazebo camera image
        won't be aligned properly with the frame it is supposedly originating from 
        <origin xyz="0 0 0" rpy="-1.57079 0 -1.57079"/>
        <parent link="camera_link"/>
        <child link="camera_link_optical"/>
        </joint> -->





<link name = "back_left_wheel">
                <inertial>
               <mass value="2"/>
              <origin xyz = '0 0 0' rpy= "0 1.57 0"/>
              <inertia ixx="0.03166666666" ixy="0" ixz="0" iyy="0.03166666666" iyz="0" izz="0.0625"/>
             </inertial>

             <collision name="back_left_wheel_collision">
                <origin xyz = '0 0 0' rpy= "0 1.57 0"/>
                <geometry>
                  <cylinder length = '0.05' radius = '0.25' />
               </geometry>
             </collision>
		<visual>
        	<geometry>
        		<cylinder length = '0.05' radius = '0.25' />
      		</geometry>
          	<origin xyz = '0 0 0' rpy= "0 1.57 0"/>
        </visual>
	</link>
	<joint name = "back_left_wheel_joint" type = "continuous">
      	<axis xyz = '1 0 0'/>
      	<parent link = 'base'/>
      	<child link = 'back_left_wheel'/>
      	<origin xyz = '0.53 0.4 0'/>
    </joint>
	
	<link name = "back_right_wheel">
               <inertial>
               <mass value="2"/>
              <origin xyz = '0 0 0' rpy= "0 1.57 0"/>
              <inertia ixx="0.03166666666" ixy="0" ixz="0" iyy="0.03166666666" iyz="0" izz="0.0625"/>
             </inertial>
             <collision name="back_right_wheel_collision">
                <origin xyz = '0 0 0' rpy= "0 1.57 0"/>
                <geometry>
                  <cylinder length = '0.05' radius = '0.25' />
               </geometry>
             </collision>
		<visual>
        	<geometry>
        		<cylinder length = '0.05' radius = '0.25' />
      		</geometry>
          	<origin xyz = '0 0 0' rpy= "0 1.57 0"/>
        </visual>
	</link>
	<joint name = "back_right_wheel_joint" type = "continuous">
      	<axis xyz = '1 0 0'/>
      	<parent link = 'base'/>
      	<child link = 'back_right_wheel'/>
      	<origin xyz = '-0.53 0.4 0'/>
    </joint>

	<link name = "front_left_wheel">
                 <inertial>
               <mass value="2"/>
              <origin xyz = '0 0 0' rpy= "0 1.57 0"/>
              <inertia ixx="0.03166666666" ixy="0" ixz="0" iyy="0.03166666666" iyz="0" izz="0.0625"/>
             </inertial>
              <collision name="front_left_wheel_collision">
                <origin xyz = '0 0 0' rpy= "0 1.57 0"/>
                <geometry>
                  <cylinder length = '0.05' radius = '0.25' />
               </geometry>
             </collision>
		<visual>
        	<geometry>
        		<cylinder length = '0.05' radius = '0.25' />
      		</geometry>
          	<origin xyz = '0 0 0' rpy= "0 1.57 0"/>
        </visual>
	</link>
	<joint name = "front_left_wheel_joint" type = "continuous">
      	<axis xyz = '1 0 0'/>
      	<parent link = 'base'/>
      	<child link = 'front_left_wheel'/>
      	<origin xyz = '0.53 -0.4 0'/>
    </joint>
	
	<link name = "front_right_wheel">
               <inertial>
               <mass value="2"/>
              <origin xyz = '0 0 0' rpy= "0 1.57 0"/>
              <inertia ixx="0.03166666666" ixy="0" ixz="0" iyy="0.03166666666" iyz="0" izz="0.0625"/>
             </inertial>
             <collision name="front_right_wheel_collision">
                <origin xyz = '0 0 0' rpy= "0 1.57 0"/>
                <geometry>
                  <cylinder length = '0.05' radius = '0.25' />
               </geometry>
             </collision>
		<visual>
        	<geometry>
        		<cylinder length = '0.05' radius = '0.25' />
      		</geometry>
          	<origin xyz = '0 0 0' rpy= "0 1.57 0"/>
        </visual>
	</link>
	<joint name = "front_right_wheel_joint" type = "continuous">
      	<axis xyz = '1 0 0'/>
      	<parent link = 'base'/>
      	<child link = 'front_right_wheel'/>
      	<origin xyz = '-0.53 -0.4 0'/>
    </joint>
	

        	<link name = "arm_base">
               <inertial>
               <mass value="0.5"/>
              <origin xyz = '0 0 0.2'/>
              <inertia ixx="0.00541666666" ixy="0" ixz="0" iyy="0.00541666666" iyz="0" izz="0.00541666666"/>
             </inertial>
              <collision name="arm_base_collision">
                <origin xyz = '0 0 0.2'/>
                <geometry>
                  <box size = '0.2 0.2 0.3' />
               </geometry>
             </collision>
  		<visual>
      		<geometry>
        		<box size = '0.2 0.2 0.3' />
      		</geometry>
          	<origin xyz = '0 0 0.2'/>
                
    	</visual>
 
	</link>

        <joint name = "arm_base_joint" type = "fixed">
      	<axis xyz = '1 0 0'/>
      	<parent link = 'base'/>
      	<child link = 'arm_base'/>
      	<origin xyz = '0 0 0'/>
    </joint>

  
	<link name = "arm_gun">
                <inertial>
               <mass value="0.5"/>
              <origin xyz = '0 0.1 0.35' rpy= "1.57 0 0"/>
              <inertia ixx="0.00791666666" ixy="0" ixz="0" iyy="0.00791666666" iyz="0" izz="0.0025"/>
             </inertial>
             <collision name="arm_gun_collision">
                <origin xyz = '0 0.1 0.35' rpy= "1.57 0 0"/>
                <geometry>
                  <cylinder length = '0.4' radius = '0.1' />
               </geometry>
             </collision>
		<visual>
        	<geometry>
        		<cylinder length = '0.4' radius = '0.1' />
      		</geometry>
          	<origin xyz = '0 0.1 0.35' rpy= "1.57 0 0"/>
        </visual>
	</link>

	<joint name = "arm_gun" type = "revolute">
      	<axis xyz = '0 0 1'/>
      	<parent link = 'arm_base'/>
      	<child link = 'arm_gun'/>
      	<origin xyz = '0 0 0'/>
      	<limit lower = "-0.5" upper = "0.5" effort = "10" velocity = "3"/>
    </joint>


  <joint name="hokuyo_joint" type="fixed">
    <axis xyz="0 1 0" />
    <origin xyz="0 0 0" rpy="0 0 0"/>
    <parent link="base"/>
    <child link="hokuyo_link"/>
  </joint>

  <!-- Hokuyo Laser -->
  <link name="hokuyo_link">
    <collision>
      <origin xyz="0 0.5 0.05" rpy="0 0 0"/>
      <geometry>
    <box size="0.1 0.1 0.1"/>
      </geometry>
    </collision>

    <visual>
      <origin xyz="0 0.5 0.05" rpy="0 0 0"/>
      <geometry>
        <mesh filename="package://workshop_demo/meshes/hokuyo.dae"/>
      </geometry>
    </visual>

    <inertial>
      <mass value="1e-5" />
      <origin xyz="0 0.5 0.05" rpy="0 0 0"/>
      <inertia ixx="1e-6" ixy="0" ixz="0" iyy="1e-6" iyz="0" izz="1e-6" />
    </inertial>
  </link>



<!-- ***************************************************************************************************************************-->
<!-- ***************************************************************************************************************************-->
<!-- ***************************************************************************************************************************-->


<gazebo>
  <plugin name="skid_steer_drive_controller" filename="libgazebo_ros_skid_steer_drive.so">
    <updateRate>20.0</updateRate>
    <robotNamespace>/</robotNamespace>
    <leftFrontJoint>front_left_wheel_joint</leftFrontJoint>
    <rightFrontJoint>front_right_wheel_joint</rightFrontJoint>
    <leftRearJoint>back_left_wheel_joint</leftRearJoint>
    <rightRearJoint>back_right_wheel_joint</rightRearJoint>
    <wheelSeparation>1</wheelSeparation>
    <wheelDiameter>0.5</wheelDiameter>
    <robotBaseFrame>base_link</robotBaseFrame>
    <torque>10</torque>
    <topicName>cmd_vel</topicName>
    <broadcastTF>false</broadcastTF>
  </plugin>
</gazebo>


    <gazebo>
        <plugin name="gazebo_ros_control" filename="libgazebo_ros_control.so">
          <robotNamespace>/</robotNamespace>
        </plugin>
      </gazebo>


<gazebo reference="camera_link">
  <sensor name="camera1" type="depth">
    <update_rate>20.0</update_rate>
    <camera>
      <horizontal_fov>1.047198</horizontal_fov>
      <image>
        <width>800</width>
        <height>800</height>
        <format>R8G8B8</format>
      </image>
      <clip>
        <near>0.02</near>
        <far>300</far>
      </clip>
    </camera>
    <plugin name="camera_controller" filename="libgazebo_ros_openni_kinect.so">
      <baseline>0.2</baseline>
      <alwaysOn>false</alwaysOn>
      <updateRate>0.0</updateRate>
      <cameraName>robo_gazebo/camera1</cameraName>
      <imageTopicName>image_raw</imageTopicName>
      <cameraInfoTopicName>camera_info</cameraInfoTopicName>
      <depthImageTopicName>/1/depth/image_raw</depthImageTopicName>
      <depthImageInfoTopicName>/1/depth/camera_info</depthImageInfoTopicName>
      <pointCloudTopicName>/1/depth/points</pointCloudTopicName>
      <frameName>camera_link</frameName>
      <pointCloudCutoff>0.5</pointCloudCutoff>
      <pointCloudCutoffMax>3.0</pointCloudCutoffMax>
      <distortionK1>0.00000001</distortionK1>
      <distortionK2>0.00000001</distortionK2>
      <distortionK3>0.00000001</distortionK3>
      <distortionT1>0.00000001</distortionT1>
      <distortionT2>0.00000001</distortionT2>
      <CxPrime>0</CxPrime>
      <Cx>0</Cx>
      <Cy>0</Cy>
      <focalLength>0</focalLength>
      <hackBaseline>0</hackBaseline>
    </plugin>
  </sensor>
</gazebo>

   <gazebo reference="hokuyo_link">
    <sensor type="gpu_ray" name="head_hokuyo_sensor">
      <pose>0 0 0 0 0 0</pose>
      <visualize>true</visualize>
      <update_rate>40</update_rate>
      <ray>
        <scan>
          <horizontal>
            <samples>720</samples>
            <resolution>1</resolution>
            <min_angle>0.52359</min_angle>
            <max_angle>2.094</max_angle>
          </horizontal>
        </scan>
        <range>
          <min>0.10</min>
          <max>30.0</max>
          <resolution>0.01</resolution>
        </range>
        <noise>
          <type>gaussian</type>
          <!-- Noise parameters based on published spec for Hokuyo laser
               achieving "+-30mm" accuracy at range < 10m.  A mean of 0.0m and
               stddev of 0.01m will put 99.7% of samples within 0.03m of the true
               reading. -->
          <mean>0.0</mean>
          <stddev>0.01</stddev>
        </noise>
      </ray>
      <plugin name="gazebo_ros_head_hokuyo_controller" filename="libgazebo_ros_gpu_laser.so">
        <laserName>robo_gazebo/laser1</laserName>
        <topicName>laser_scan</topicName>
        <frameName>hokuyo_link</frameName>
      </plugin>
    </sensor>
  </gazebo>
  
</robot>
